<mujoco model="simple_arm">
  <compiler angle="degree"/>
  <option integrator="RK4" timestep="0.01"/>

  <visual>
    <global offheight="720"/>
  </visual>

  <worldbody>    
    <light name="main_light" pos="0 1 2" dir="0 -1 -1"/>
    <camera name="my_camera" mode="targetbody" pos="0 1 3" target="arm"/>

    <!-- Define the base of the robot -->
    <body name="base" pos="0 0 0">
      <geom type="box" size="0.1 0.1 0.1" rgba="0.8 0.8 0.8 1"/>
      
      <!-- Define the rotating arm -->
      <body name="arm" pos="0 0 0.1">
        <joint name="arm_joint" type="hinge" axis="0 0 1"/>
        <geom name="arm_body" type="box" size="0.05 0.05 0.4" pos="0 0 0.4" rgba="0.2 0.6 0.8 1"/>
        <geom name="arm_tip" type="box" size="0.05 0.2 0.05" pos="0 0.15 0.85" rgba="1 0 0 1"/>
      </body>
    </body>

    <body name="ball" pos="0.2 0.3 0.95">
      <geom name="ball_geom" type="sphere" size="0.05" rgba="0 1 0 1" contype="0" conaffinity="0"/>
    </body>


  </worldbody>

  <actuator>
    <motor joint="arm_joint" ctrlrange="-1 1" ctrllimited="true"/>
  </actuator>
</mujoco>